2022-04-03 17:11:41,883 - instabot version: 0.117.0 (bot) - INFO - Instabot version: 0.117.0 Started
2022-04-03 17:11:41,883 - instabot version: 0.117.0 (bot) - DEBUG - Bot imported from C:\Users\demen\AppData\Local\Programs\Python\Python38\lib\site-packages\instabot\bot\bot.py
2022-04-03 17:11:41,884 - instabot version: 0.117.0 (api_login) - INFO - Not yet logged in starting: PRE-LOGIN FLOW!
2022-04-03 17:11:41,891 - instabot version: 0.117.0 (api) - WARNING - HTTPSConnectionPool(host='i.instagram.com', port=443): Max retries exceeded with url: /api/v1/accounts/get_prefill_candidates/ (Caused by NewConnectionError('<urllib3.connection.HTTPSConnection object at 0x000001A2B6365550>: Failed to establish a new connection: [Errno 11002] getaddrinfo failed'))
2022-04-03 17:11:41,899 - instabot version: 0.117.0 (api) - WARNING - HTTPSConnectionPool(host='i.instagram.com', port=443): Max retries exceeded with url: /api/v1/qe/sync/ (Caused by NewConnectionError('<urllib3.connection.HTTPSConnection object at 0x000001A2B63655B0>: Failed to establish a new connection: [Errno 11002] getaddrinfo failed'))
2022-04-03 17:11:41,902 - instabot version: 0.117.0 (api) - WARNING - HTTPSConnectionPool(host='i.instagram.com', port=443): Max retries exceeded with url: /api/v1/launcher/sync/ (Caused by NewConnectionError('<urllib3.connection.HTTPSConnection object at 0x000001A2B6365640>: Failed to establish a new connection: [Errno 11002] getaddrinfo failed'))
2022-04-03 17:11:41,903 - instabot version: 0.117.0 (api) - WARNING - HTTPSConnectionPool(host='i.instagram.com', port=443): Max retries exceeded with url: /api/v1/accounts/contact_point_prefill/ (Caused by NewConnectionError('<urllib3.connection.HTTPSConnection object at 0x000001A2B63655B0>: Failed to establish a new connection: [Errno 11002] getaddrinfo failed'))
