2022-04-03 17:08:51,677 - instabot version: 0.117.0 (bot) - INFO - Instabot version: 0.117.0 Started
2022-04-03 17:08:51,677 - instabot version: 0.117.0 (bot) - DEBUG - Bot imported from C:\Users\demen\AppData\Local\Programs\Python\Python38\lib\site-packages\instabot\bot\bot.py
2022-04-03 17:08:51,678 - instabot version: 0.117.0 (api_login) - INFO - Not yet logged in starting: PRE-LOGIN FLOW!
2022-04-03 17:08:51,685 - instabot version: 0.117.0 (api) - WARNING - HTTPSConnectionPool(host='i.instagram.com', port=443): Max retries exceeded with url: /api/v1/accounts/get_prefill_candidates/ (Caused by NewConnectionError('<urllib3.connection.HTTPSConnection object at 0x000001EA57266550>: Failed to establish a new connection: [Errno 11002] getaddrinfo failed'))
2022-04-03 17:08:51,687 - instabot version: 0.117.0 (api) - WARNING - HTTPSConnectionPool(host='i.instagram.com', port=443): Max retries exceeded with url: /api/v1/qe/sync/ (Caused by NewConnectionError('<urllib3.connection.HTTPSConnection object at 0x000001EA572665B0>: Failed to establish a new connection: [Errno 11002] getaddrinfo failed'))
2022-04-03 17:08:51,689 - instabot version: 0.117.0 (api) - WARNING - HTTPSConnectionPool(host='i.instagram.com', port=443): Max retries exceeded with url: /api/v1/launcher/sync/ (Caused by NewConnectionError('<urllib3.connection.HTTPSConnection object at 0x000001EA57266640>: Failed to establish a new connection: [Errno 11002] getaddrinfo failed'))
2022-04-03 17:08:51,691 - instabot version: 0.117.0 (api) - WARNING - HTTPSConnectionPool(host='i.instagram.com', port=443): Max retries exceeded with url: /api/v1/accounts/contact_point_prefill/ (Caused by NewConnectionError('<urllib3.connection.HTTPSConnection object at 0x000001EA572665B0>: Failed to establish a new connection: [Errno 11002] getaddrinfo failed'))
