2022-04-03 17:00:03,137 - instabot version: 0.117.0 (bot) - INFO - Instabot version: 0.117.0 Started
2022-04-03 17:00:03,137 - instabot version: 0.117.0 (bot) - DEBUG - Bot imported from C:\Users\demen\AppData\Local\Programs\Python\Python38\lib\site-packages\instabot\bot\bot.py
2022-04-03 17:00:03,138 - instabot version: 0.117.0 (api_login) - INFO - Not yet logged in starting: PRE-LOGIN FLOW!
2022-04-03 17:00:03,145 - instabot version: 0.117.0 (api) - WARNING - HTTPSConnectionPool(host='i.instagram.com', port=443): Max retries exceeded with url: /api/v1/accounts/get_prefill_candidates/ (Caused by NewConnectionError('<urllib3.connection.HTTPSConnection object at 0x000002410C856550>: Failed to establish a new connection: [Errno 11002] getaddrinfo failed'))
2022-04-03 17:00:03,153 - instabot version: 0.117.0 (api) - WARNING - HTTPSConnectionPool(host='i.instagram.com', port=443): Max retries exceeded with url: /api/v1/qe/sync/ (Caused by NewConnectionError('<urllib3.connection.HTTPSConnection object at 0x000002410C8565B0>: Failed to establish a new connection: [Errno 11002] getaddrinfo failed'))
2022-04-03 17:00:03,155 - instabot version: 0.117.0 (api) - WARNING - HTTPSConnectionPool(host='i.instagram.com', port=443): Max retries exceeded with url: /api/v1/launcher/sync/ (Caused by NewConnectionError('<urllib3.connection.HTTPSConnection object at 0x000002410C856640>: Failed to establish a new connection: [Errno 11002] getaddrinfo failed'))
2022-04-03 17:00:03,157 - instabot version: 0.117.0 (api) - WARNING - HTTPSConnectionPool(host='i.instagram.com', port=443): Max retries exceeded with url: /api/v1/accounts/contact_point_prefill/ (Caused by NewConnectionError('<urllib3.connection.HTTPSConnection object at 0x000002410C8565B0>: Failed to establish a new connection: [Errno 11002] getaddrinfo failed'))
