2022-04-03 17:14:20,118 - instabot version: 0.117.0 (bot) - INFO - Instabot version: 0.117.0 Started
2022-04-03 17:14:20,118 - instabot version: 0.117.0 (bot) - DEBUG - Bot imported from C:\Users\demen\AppData\Local\Programs\Python\Python38\lib\site-packages\instabot\bot\bot.py
2022-04-03 17:14:20,118 - instabot version: 0.117.0 (api_login) - INFO - Not yet logged in starting: PRE-LOGIN FLOW!
2022-04-03 17:14:20,125 - instabot version: 0.117.0 (api) - WARNING - HTTPSConnectionPool(host='i.instagram.com', port=443): Max retries exceeded with url: /api/v1/accounts/get_prefill_candidates/ (Caused by NewConnectionError('<urllib3.connection.HTTPSConnection object at 0x000001EC69074D00>: Failed to establish a new connection: [Errno 11002] getaddrinfo failed'))
2022-04-03 17:14:20,133 - instabot version: 0.117.0 (api) - WARNING - HTTPSConnectionPool(host='i.instagram.com', port=443): Max retries exceeded with url: /api/v1/qe/sync/ (Caused by NewConnectionError('<urllib3.connection.HTTPSConnection object at 0x000001EC69074D60>: Failed to establish a new connection: [Errno 11002] getaddrinfo failed'))
2022-04-03 17:14:20,135 - instabot version: 0.117.0 (api) - WARNING - HTTPSConnectionPool(host='i.instagram.com', port=443): Max retries exceeded with url: /api/v1/launcher/sync/ (Caused by NewConnectionError('<urllib3.connection.HTTPSConnection object at 0x000001EC69074DF0>: Failed to establish a new connection: [Errno 11002] getaddrinfo failed'))
2022-04-03 17:14:20,138 - instabot version: 0.117.0 (api) - WARNING - HTTPSConnectionPool(host='i.instagram.com', port=443): Max retries exceeded with url: /api/v1/accounts/contact_point_prefill/ (Caused by NewConnectionError('<urllib3.connection.HTTPSConnection object at 0x000001EC69074D60>: Failed to establish a new connection: [Errno 11002] getaddrinfo failed'))
